Workbook

Sheet Apple Historical Data
A1: Date | B1: Close/Last | C1: Volume | D1: Open | E1: High | F1: Low
A2: 09/19/2025 | B2: 245.5 | C2: 163741300 | D2: 241.225 | E2: 246.3 | F2: 240.2106
A3: 09/18/2025 | B3: 237.88 | C3: 44249580 | D3: 239.97 | E3: 241.2 | F3: 236.65
A4: 09/17/2025 | B4: 238.99 | C4: 46508020 | D4: 238.97 | E4: 240.1 | F4: 237.7301
A5: 09/16/2025 | B5: 238.15 | C5: 63421100 | D5: 237.175 | E5: 241.22 | F5: 236.3235
A6: 09/15/2025 | B6: 236.7 | C6: 42699520 | D6: 237 | E6: 238.19 | F6: 235.03
A7: 46000 | B7: 234.07 | C7: 55824220 | D7: 229.22 | E7: 234.51 | F7: 229.02
A8: 45970 | B8: 230.03 | C8: 50208580 | D8: 226.875 | E8: 230.45 | F8: 226.65
A9: 45939 | B9: 226.79 | C9: 83440810 | D9: 232.185 | E9: 232.42 | F9: 225.95
A10: 45909 | B10: 234.35 | C10: 66313920 | D10: 237 | E10: 238.7805 | F10: 233.36
A11: 45878 | B11: 237.88 | C11: 48999500 | D11: 239.3 | E11: 240.15 | F11: 236.34
A12: 45786 | B12: 239.69 | C12: 54870400 | D12: 239.995 | E12: 241.32 | F12: 238.4901
A13: 45756 | B13: 239.78 | C13: 47549430 | D13: 238.45 | E13: 239.8999 | F13: 236.74
A14: 45725 | B14: 238.47 | C14: 66427840 | D14: 237.21 | E14: 238.85 | F14: 234.36
A15: 45697 | B15: 229.72 | C15: 44075640 | D15: 229.25 | E15: 230.85 | F15: 226.97
A16: 08/29/2025 | B16: 232.14 | C16: 39418440 | D16: 232.51 | E16: 233.38 | F16: 231.37
A17: 08/28/2025 | B17: 232.56 | C17: 38074700 | D17: 230.82 | E17: 233.41 | F17: 229.335
A18: 08/27/2025 | B18: 230.49 | C18: 31259510 | D18: 228.61 | E18: 230.9 | F18: 228.26
A19: 08/26/2025 | B19: 229.31 | C19: 54575110 | D19: 226.87 | E19: 229.49 | F19: 224.69
A20: 08/25/2025 | B20: 227.16 | C20: 30983130 | D20: 226.48 | E20: 229.3 | F20: 226.23
A21: 08/22/2025 | B21: 227.76 | C21: 42477810 | D21: 226.17 | E21: 229.09 | F21: 225.41
A22: 08/21/2025 | B22: 224.9 | C22: 30621250 | D22: 226.27 | E22: 226.52 | F22: 223.7804
A23: 08/20/2025 | B23: 226.01 | C23: 42263870 | D23: 229.98 | E23: 230.47 | F23: 225.77
A24: 08/19/2025 | B24: 230.56 | C24: 39402560 | D24: 231.275 | E24: 232.87 | F24: 229.35
A25: 08/18/2025 | B25: 230.89 | C25: 37476190 | D25: 231.7 | E25: 233.12 | F25: 230.11
A26: 08/15/2025 | B26: 231.59 | C26: 56038660 | D26: 234 | E26: 234.28 | F26: 229.335
A27: 08/14/2025 | B27: 232.78 | C27: 51916280 | D27: 234.055 | E27: 235.12 | F27: 230.85
A28: 08/13/2025 | B28: 233.33 | C28: 69878550 | D28: 231.07 | E28: 235 | F28: 230.43
A29: 45999 | B29: 229.65 | C29: 55672300 | D29: 228.005 | E29: 230.8 | F29: 227.07
A30: 45969 | B30: 227.18 | C30: 61806130 | D30: 227.92 | E30: 229.56 | F30: 224.76
A31: 45877 | B31: 229.35 | C31: 113854000 | D31: 220.83 | E31: 231 | F31: 219.25
A32: 45846 | B32: 220.03 | C32: 90224830 | D32: 218.875 | E32: 220.85 | F32: 216.58
A33: 45816 | B33: 213.25 | C33: 108483100 | D33: 205.63 | E33: 215.38 | F33: 205.59
A34: 45785 | B34: 202.92 | C34: 44155080 | D34: 203.4 | E34: 205.34 | F34: 202.16
A35: 45755 | B35: 203.35 | C35: 75109300 | D35: 204.505 | E35: 207.88 | F35: 201.675
A36: 45665 | B36: 202.38 | C36: 104434500 | D36: 210.865 | E36: 213.58 | F36: 201.5
A37: 07/31/2025 | B37: 207.57 | C37: 80698430 | D37: 208.49 | E37: 209.84 | F37: 207.16
A38: 07/30/2025 | B38: 209.05 | C38: 45512510 | D38: 211.895 | E38: 212.39 | F38: 207.72
A39: 07/29/2025 | B39: 211.27 | C39: 51411720 | D39: 214.175 | E39: 214.81 | F39: 210.82
A40: 07/28/2025 | B40: 214.05 | C40: 37858020 | D40: 214.03 | E40: 214.845 | F40: 213.06
...

Sheet Parameters
A1: Date | B1: Close/Last | C1: Daily Log Returns | E1: Daily | G1: rt ~ N(0.0008524,0.0003374)
A2: 09/19/2025 | B2: 245.5 | C2: =LN(B2/B3) -> 0.031530602 | E2: Average | F2: =AVERAGE(C2:C932) -> 0.0003214128 | G2: pt ~ LN(0.0008524,0.0003374)
A3: 09/18/2025 | B3: 237.88 | C3: =LN(B3/B4) -> -0.0046553652 | E3: Std | F3: =_xlfn.STDEV.S(C2:C932) -> 0.018274815
A4: 09/17/2025 | B4: 238.99 | C4: =LN(B4/B5) -> 0.0035209828 | E4: Var | F4: =F3^2 -> 0.00033396885
A5: 09/16/2025 | B5: 238.15 | C5: =LN(B5/B6) -> 0.0061072107
A6: 09/15/2025 | B6: 236.7 | C6: =LN(B6/B7) -> 0.011173301 | E6: Weekly | G6: rweek ~ N(0.0042618,0.0016869)
A7: 46000 | B7: 234.07 | C7: =LN(B7/B8) -> 0.017410481 | E7: Average | F7: =F2*5 -> 0.001607064
A8: 45970 | B8: 230.03 | C8: =LN(B8/B9) -> 0.014185256 | E8: Std | F8: =F3*SQRT(5) -> 0.040863728
A9: 45939 | B9: 226.79 | C9: =LN(B9/B10) -> -0.032791245 | E9: Var | F9: =F8^2 -> 0.0016698442
A10: 45909 | B10: 234.35 | C10: =LN(B10/B11) -> -0.01495062
A11: 45878 | B11: 237.88 | C11: =LN(B11/B12) -> -0.0075800769
A12: 45786 | B12: 239.69 | C12: =LN(B12/B13) -> -0.00037541452 | E12: Values prior to 3rd of Jan 2022 omitted
A13: 45756 | B13: 239.78 | C13: =LN(B13/B14) -> 0.00547832
A14: 45725 | B14: 238.47 | C14: =LN(B14/B15) -> 0.03738234
A15: 45697 | B15: 229.72 | C15: =LN(B15/B16) -> -0.010479462
A16: 08/29/2025 | B16: 232.14 | C16: =LN(B16/B17) -> -0.0018076183
A17: 08/28/2025 | B17: 232.56 | C17: =LN(B17/B18) -> 0.0089407787
A18: 08/27/2025 | B18: 230.49 | C18: =LN(B18/B19) -> 0.0051326776
A19: 08/26/2025 | B19: 229.31 | C19: =LN(B19/B20) -> 0.0094201849
A20: 08/25/2025 | B20: 227.16 | C20: =LN(B20/B21) -> -0.002637828
A21: 08/22/2025 | B21: 227.76 | C21: =LN(B21/B22) -> 0.012636584
A22: 08/21/2025 | B22: 224.9 | C22: =LN(B22/B23) -> -0.0049233871
A23: 08/20/2025 | B23: 226.01 | C23: =LN(B23/B24) -> -0.019931886
A24: 08/19/2025 | B24: 230.56 | C24: =LN(B24/B25) -> -0.0014302744
A25: 08/18/2025 | B25: 230.89 | C25: =LN(B25/B26) -> -0.0030271602
A26: 08/15/2025 | B26: 231.59 | C26: =LN(B26/B27) -> -0.0051252346
A27: 08/14/2025 | B27: 232.78 | C27: =LN(B27/B28) -> -0.002359959
A28: 08/13/2025 | B28: 233.33 | C28: =LN(B28/B29) -> 0.01589735
A29: 45999 | B29: 229.65 | C29: =LN(B29/B30) -> 0.010813756
A30: 45969 | B30: 227.18 | C30: =LN(B30/B31) -> -0.0095065662
A31: 45877 | B31: 229.35 | C31: =LN(B31/B32) -> 0.04148532
A32: 45846 | B32: 220.03 | C32: =LN(B32/B33) -> 0.031298714
A33: 45816 | B33: 213.25 | C33: =LN(B33/B34) -> 0.049653374
A34: 45785 | B34: 202.92 | C34: =LN(B34/B35) -> -0.0021168197
A35: 45755 | B35: 203.35 | C35: =LN(B35/B36) -> 0.0047815141
A36: 45665 | B36: 202.38 | C36: =LN(B36/B37) -> -0.025321514
A37: 07/31/2025 | B37: 207.57 | C37: =LN(B37/B38) -> -0.0071048256
A38: 07/30/2025 | B38: 209.05 | C38: =LN(B38/B39) -> -0.010563479
A39: 07/29/2025 | B39: 211.27 | C39: =LN(B39/B40) -> -0.013072696
A40: 07/28/2025 | B40: 214.05 | C40: =LN(B40/B41) -> 0.00079452251
...

Sheet Simulations | Acc. Wealth
B2: Daily | D2: rt ~ N(0.0003214,0.000334) | G2: Sims of rweek
B3: Average | C3: =Parameters!F2 -> 0.0003214128 | D3: pt ~ LN(0.0003214,0.000334) | F3: Week | G3: 1 | H3: =G3+1 -> 2 | I3: =H3+1 -> 3 | J3: =I3+1 -> 4 | K3: =J3+1 -> 5 | L3: =K3+1 -> 6 | M3: =L3+1 -> 7 | N3: =M3+1 -> 8 | O3: =N3+1 -> 9 | ... ALR3: =ALQ3+1 -> 1000
B4: Std | C4: =Parameters!F3 -> 0.018274815 | F4: 1 | G4: =_xlfn.NORM.INV(RAND(),$C$8,$C$9) -> 0.015530367 | H4: =_xlfn.NORM.INV(RAND(),$C$8,$C$9) -> -0.018744358 | I4: =_xlfn.NORM.INV(RAND(),$C$8,$C$9) -> -0.042101427 | J4: =_xlfn.NORM.INV(RAND(),$C$8,$C$9) -> 0.0075938684 | K4: =_xlfn.NORM.INV(RAND(),$C$8,$C$9) -> 0.015522279 | L4: =_xlfn.NORM.INV(RAND(),$C$8,$C$9) -> 0.051241362 | M4: =_xlfn.NORM.INV(RAND(),$C$8,$C$9) -> -0.025806897 | N4: =_xlfn.NORM.INV(RAND(),$C$8,$C$9) -> 0.045532134 | ... ALR4: =_xlfn.NORM.INV(RAND(),$C$8,$C$9) -> 0.047188757
B5: Var | C5: =C4^2 -> 0.00033396885 | F5: 2 | G5: =_xlfn.NORM.INV(RAND(),$C$8,$C$9) -> -0.034121228 | H5: =_xlfn.NORM.INV(RAND(),$C$8,$C$9) -> -0.0052110336 | I5: =_xlfn.NORM.INV(RAND(),$C$8,$C$9) -> 0.033392628 | J5: =_xlfn.NORM.INV(RAND(),$C$8,$C$9) -> 0.0079956734 | K5: =_xlfn.NORM.INV(RAND(),$C$8,$C$9) -> 0.0080352815 | L5: =_xlfn.NORM.INV(RAND(),$C$8,$C$9) -> 0.038567222 | M5: =_xlfn.NORM.INV(RAND(),$C$8,$C$9) -> -0.016897437 | N5: =_xlfn.NORM.INV(RAND(),$C$8,$C$9) -> -0.0079460248 | ... ALR5: =_xlfn.NORM.INV(RAND(),$C$8,$C$9) -> 0.0035172408
F6: =F5+1 -> 3 | G6: =_xlfn.NORM.INV(RAND(),$C$8,$C$9) -> 0.0072728055 | H6: =_xlfn.NORM.INV(RAND(),$C$8,$C$9) -> -0.050441232 | I6: =_xlfn.NORM.INV(RAND(),$C$8,$C$9) -> -0.034627278 | J6: =_xlfn.NORM.INV(RAND(),$C$8,$C$9) -> -0.0098023992 | K6: =_xlfn.NORM.INV(RAND(),$C$8,$C$9) -> 0.099839911 | L6: =_xlfn.NORM.INV(RAND(),$C$8,$C$9) -> 0.042079972 | M6: =_xlfn.NORM.INV(RAND(),$C$8,$C$9) -> 0.010567396 | N6: =_xlfn.NORM.INV(RAND(),$C$8,$C$9) -> 0.00041561279 | ... ALR6: =_xlfn.NORM.INV(RAND(),$C$8,$C$9) -> 0.0048752114
B7: Weekly | D7: rweek ~ N(0.001607,0.00167) | F7: =F6+1 -> 4 | G7: =_xlfn.NORM.INV(RAND(),$C$8,$C$9) -> -0.023345936 | H7: =_xlfn.NORM.INV(RAND(),$C$8,$C$9) -> -0.036197959 | I7: =_xlfn.NORM.INV(RAND(),$C$8,$C$9) -> -0.030864239 | J7: =_xlfn.NORM.INV(RAND(),$C$8,$C$9) -> -0.015805886 | K7: =_xlfn.NORM.INV(RAND(),$C$8,$C$9) -> 0.0025570978 | L7: =_xlfn.NORM.INV(RAND(),$C$8,$C$9) -> 0.010065413 | M7: =_xlfn.NORM.INV(RAND(),$C$8,$C$9) -> 0.042586189 | N7: =_xlfn.NORM.INV(RAND(),$C$8,$C$9) -> 0.01989302 | ... ALR7: =_xlfn.NORM.INV(RAND(),$C$8,$C$9) -> -0.051554857
B8: Average | C8: =Parameters!F7 -> 0.001607064 | D8: pweek ~ LN(0.001607,0.00167) | F8: =F7+1 -> 5 | G8: =_xlfn.NORM.INV(RAND(),$C$8,$C$9) -> -0.019290159 | H8: =_xlfn.NORM.INV(RAND(),$C$8,$C$9) -> 0.00022597275 | I8: =_xlfn.NORM.INV(RAND(),$C$8,$C$9) -> 0.017871669 | J8: =_xlfn.NORM.INV(RAND(),$C$8,$C$9) -> -0.0046749894 | K8: =_xlfn.NORM.INV(RAND(),$C$8,$C$9) -> 0.030295934 | L8: =_xlfn.NORM.INV(RAND(),$C$8,$C$9) -> -0.020414952 | M8: =_xlfn.NORM.INV(RAND(),$C$8,$C$9) -> -0.0025349821 | N8: =_xlfn.NORM.INV(RAND(),$C$8,$C$9) -> 0.025691288 | ... ALR8: =_xlfn.NORM.INV(RAND(),$C$8,$C$9) -> 0.0043404463
B9: Std | C9: =Parameters!F8 -> 0.040863728 | F9: =F8+1 -> 6 | G9: =_xlfn.NORM.INV(RAND(),$C$8,$C$9) -> 0.058029083 | H9: =_xlfn.NORM.INV(RAND(),$C$8,$C$9) -> -0.10782777 | I9: =_xlfn.NORM.INV(RAND(),$C$8,$C$9) -> -0.020069066 | J9: =_xlfn.NORM.INV(RAND(),$C$8,$C$9) -> 0.0012786292 | K9: =_xlfn.NORM.INV(RAND(),$C$8,$C$9) -> 0.018630246 | L9: =_xlfn.NORM.INV(RAND(),$C$8,$C$9) -> 0.074799616 | M9: =_xlfn.NORM.INV(RAND(),$C$8,$C$9) -> -0.017791819 | N9: =_xlfn.NORM.INV(RAND(),$C$8,$C$9) -> 0.026797297 | ... ALR9: =_xlfn.NORM.INV(RAND(),$C$8,$C$9) -> -0.0081684156
B10: Var | C10: =C9^2 -> 0.0016698442 | F10: =F9+1 -> 7 | G10: =_xlfn.NORM.INV(RAND(),$C$8,$C$9) -> -0.064730894 | H10: =_xlfn.NORM.INV(RAND(),$C$8,$C$9) -> -0.031256513 | I10: =_xlfn.NORM.INV(RAND(),$C$8,$C$9) -> 0.033377672 | J10: =_xlfn.NORM.INV(RAND(),$C$8,$C$9) -> 0.031141788 | K10: =_xlfn.NORM.INV(RAND(),$C$8,$C$9) -> 0.065578643 | L10: =_xlfn.NORM.INV(RAND(),$C$8,$C$9) -> -0.011779776 | M10: =_xlfn.NORM.INV(RAND(),$C$8,$C$9) -> 0.012496961 | N10: =_xlfn.NORM.INV(RAND(),$C$8,$C$9) -> -0.054900563 | ... ALR10: =_xlfn.NORM.INV(RAND(),$C$8,$C$9) -> 0.008212598
B11: Initial Investment | D11: 57661 | F11: =F10+1 -> 8 | G11: =_xlfn.NORM.INV(RAND(),$C$8,$C$9) -> 0.015069956 | H11: =_xlfn.NORM.INV(RAND(),$C$8,$C$9) -> 0.093348662 | I11: =_xlfn.NORM.INV(RAND(),$C$8,$C$9) -> 0.031633369 | J11: =_xlfn.NORM.INV(RAND(),$C$8,$C$9) -> -0.0017232076 | K11: =_xlfn.NORM.INV(RAND(),$C$8,$C$9) -> 0.010170709 | L11: =_xlfn.NORM.INV(RAND(),$C$8,$C$9) -> -0.0178734 | M11: =_xlfn.NORM.INV(RAND(),$C$8,$C$9) -> -0.076333532 | N11: =_xlfn.NORM.INV(RAND(),$C$8,$C$9) -> -0.017017957 | ... ALR11: =_xlfn.NORM.INV(RAND(),$C$8,$C$9) -> -0.051782479
B12: Rf rate | D12: 4.3 | F12: =F11+1 -> 9 | G12: =_xlfn.NORM.INV(RAND(),$C$8,$C$9) -> -0.0049009814 | H12: =_xlfn.NORM.INV(RAND(),$C$8,$C$9) -> -0.010736348 | I12: =_xlfn.NORM.INV(RAND(),$C$8,$C$9) -> -0.014660825 | J12: =_xlfn.NORM.INV(RAND(),$C$8,$C$9) -> -0.018243238 | K12: =_xlfn.NORM.INV(RAND(),$C$8,$C$9) -> -0.019442141 | L12: =_xlfn.NORM.INV(RAND(),$C$8,$C$9) -> 0.026451492 | M12: =_xlfn.NORM.INV(RAND(),$C$8,$C$9) -> 0.014783536 | N12: =_xlfn.NORM.INV(RAND(),$C$8,$C$9) -> -0.0093200339 | ... ALR12: =_xlfn.NORM.INV(RAND(),$C$8,$C$9) -> 0.050359378
F13: =F12+1 -> 10 | G13: =_xlfn.NORM.INV(RAND(),$C$8,$C$9) -> 0.0056167301 | H13: =_xlfn.NORM.INV(RAND(),$C$8,$C$9) -> 0.054368185 | I13: =_xlfn.NORM.INV(RAND(),$C$8,$C$9) -> -0.024177982 | J13: =_xlfn.NORM.INV(RAND(),$C$8,$C$9) -> -0.01604352 | K13: =_xlfn.NORM.INV(RAND(),$C$8,$C$9) -> 0.051354072 | L13: =_xlfn.NORM.INV(RAND(),$C$8,$C$9) -> -0.0081850916 | M13: =_xlfn.NORM.INV(RAND(),$C$8,$C$9) -> 0.0027082278 | N13: =_xlfn.NORM.INV(RAND(),$C$8,$C$9) -> -0.012813554 | ... ALR13: =_xlfn.NORM.INV(RAND(),$C$8,$C$9) -> 0.024816547
B14: Data | F14: =F13+1 -> 11 | G14: =_xlfn.NORM.INV(RAND(),$C$8,$C$9) -> -0.047907868 | H14: =_xlfn.NORM.INV(RAND(),$C$8,$C$9) -> -0.022791629 | I14: =_xlfn.NORM.INV(RAND(),$C$8,$C$9) -> 0.099205643 | J14: =_xlfn.NORM.INV(RAND(),$C$8,$C$9) -> 0.043087784 | K14: =_xlfn.NORM.INV(RAND(),$C$8,$C$9) -> 0.065356565 | L14: =_xlfn.NORM.INV(RAND(),$C$8,$C$9) -> 0.11430708 | M14: =_xlfn.NORM.INV(RAND(),$C$8,$C$9) -> -0.062774828 | N14: =_xlfn.NORM.INV(RAND(),$C$8,$C$9) -> -0.10649895 | ... ALR14: =_xlfn.NORM.INV(RAND(),$C$8,$C$9) -> -0.057666607
B15: Average Acc Wealth (Apple) | D15: =AVERAGE(G31:ALR31) -> 59618.99 | F15: =F14+1 -> 12 | G15: =_xlfn.NORM.INV(RAND(),$C$8,$C$9) -> 0.094456787 | H15: =_xlfn.NORM.INV(RAND(),$C$8,$C$9) -> 0.035413577 | I15: =_xlfn.NORM.INV(RAND(),$C$8,$C$9) -> -0.039960932 | J15: =_xlfn.NORM.INV(RAND(),$C$8,$C$9) -> -0.073203159 | K15: =_xlfn.NORM.INV(RAND(),$C$8,$C$9) -> -0.0024286859 | L15: =_xlfn.NORM.INV(RAND(),$C$8,$C$9) -> -0.0076978495 | M15: =_xlfn.NORM.INV(RAND(),$C$8,$C$9) -> 0.01928782 | N15: =_xlfn.NORM.INV(RAND(),$C$8,$C$9) -> 0.054653619 | ... ALR15: =_xlfn.NORM.INV(RAND(),$C$8,$C$9) -> 0.080750529
B16: Acc Wealth (Rf rate) | D16: =D11*(1+D12/100)^(12/52) -> 58223.945
B17: Hence, purely looking at financial results, investing into apple is the superior option | F17: Weatlh
F18: Week | G18: 1 | H18: =G18+1 -> 2 | I18: =H18+1 -> 3 | J18: =I18+1 -> 4 | K18: =J18+1 -> 5 | L18: =K18+1 -> 6 | M18: =L18+1 -> 7 | N18: =M18+1 -> 8 | O18: =N18+1 -> 9 | ... ALR18: =ALQ18+1 -> 1000
F19: 0 | G19: 57661 | H19: =G19 -> 57661 | I19: =H19 -> 57661 | J19: =I19 -> 57661 | K19: =J19 -> 57661 | L19: =K19 -> 57661 | M19: =L19 -> 57661 | N19: =M19 -> 57661 | O19: =N19 -> 57661 | ... ALR19: =ALQ19 -> 57661
F20: =1 -> 1 | G20: =EXP(G4)*G19 -> 58563.486 | H20: =EXP(H4)*H19 -> 56590.248 | I20: =EXP(I4)*I19 -> 55283.783 | J20: =EXP(J4)*J19 -> 58100.537 | K20: =EXP(K4)*K19 -> 58563.013 | L20: =EXP(L4)*L19 -> 60692.637 | M20: =EXP(M4)*M19 -> 56191.985 | N20: =EXP(N4)*N19 -> 60347.117 | ... ALR20: =EXP(ALR4)*ALR19 -> 60447.172
F21: =F20+1 -> 2 | G21: =EXP(G5)*G20 -> 56598.935 | H21: =EXP(H5)*H20 -> 56296.122 | I21: =EXP(I5)*I20 -> 57161.022 | J21: =EXP(J5)*J20 -> 58566.952 | K21: =EXP(K5)*K20 -> 59035.479 | L21: =EXP(L5)*L20 -> 63079.108 | M21: =EXP(M5)*M20 -> 55250.462 | N21: =EXP(N5)*N20 -> 59869.497 | ... ALR21: =EXP(ALR5)*ALR20 -> 60660.154
F22: =F21+1 -> 3 | G22: =EXP(G6)*G21 -> 57012.069 | H22: =EXP(H6)*H21 -> 53526.904 | I22: =EXP(I6)*I21 -> 55215.569 | J22: =EXP(J6)*J21 -> 57995.66 | K22: =EXP(K6)*K21 -> 65233.85 | L22: =EXP(L6)*L21 -> 65790.114 | M22: =EXP(M6)*M21 -> 55837.411 | N22: =EXP(N6)*N21 -> 59894.385 | ... ALR22: =EXP(ALR6)*ALR21 -> 60956.607
F23: =F22+1 -> 4 | G23: =EXP(G7)*G22 -> 55696.485 | H23: =EXP(H7)*H22 -> 51623.988 | I23: =EXP(I7)*I22 -> 53537.413 | J23: =EXP(J7)*J22 -> 57086.193 | K23: =EXP(K7)*K22 -> 65400.873 | L23: =EXP(L7)*L22 -> 66455.663 | M23: =EXP(M7)*M22 -> 58266.673 | N23: =EXP(N7)*N22 -> 61097.795 | ... ALR23: =EXP(ALR7)*ALR22 -> 57893.632
F24: =F23+1 -> 5 | G24: =EXP(G8)*G23 -> 54632.388 | H24: =EXP(H8)*H23 -> 51635.655 | I24: =EXP(I8)*I23 -> 54502.817 | J24: =EXP(J8)*J23 -> 56819.939 | K24: =EXP(K8)*K23 -> 67412.573 | L24: =EXP(L8)*L23 -> 65112.728 | M24: =EXP(M8)*M23 -> 58119.155 | N24: =EXP(N8)*N23 -> 62687.813 | ... ALR24: =EXP(ALR8)*ALR23 -> 58145.462
F25: =F24+1 -> 6 | G25: =EXP(G9)*G24 -> 57896.444 | H25: =EXP(H9)*H24 -> 46357.573 | I25: =EXP(I9)*I24 -> 53419.899 | J25: =EXP(J9)*J24 -> 56892.637 | K25: =EXP(K9)*K24 -> 68680.257 | L25: =EXP(L9)*L24 -> 70169.916 | M25: =EXP(M9)*M24 -> 57094.254 | N25: =EXP(N9)*N24 -> 64390.388 | ... ALR25: =EXP(ALR9)*ALR24 -> 57672.44
F26: =F25+1 -> 7 | G26: =EXP(G10)*G25 -> 54267.476 | H26: =EXP(H10)*H25 -> 44931.007 | I26: =EXP(I10)*I25 -> 55233.022 | J26: =EXP(J10)*J25 -> 58692.252 | K26: =EXP(K10)*K25 -> 73335.179 | L26: =EXP(L10)*L25 -> 69348.179 | M26: =EXP(M10)*M25 -> 57812.236 | N26: =EXP(N10)*N25 -> 60950.606 | ... ALR26: =EXP(ALR10)*ALR25 -> 58148.031
F27: =F26+1 -> 8 | G27: =EXP(G11)*G26 -> 55091.477 | H27: =EXP(H11)*H26 -> 49327.257 | I27: =EXP(I11)*I26 -> 57008.157 | J27: =EXP(J11)*J26 -> 58591.2 | K27: =EXP(K11)*K26 -> 74084.856 | L27: =EXP(L11)*L26 -> 68119.703 | M27: =EXP(M11)*M26 -> 53563.449 | N27: =EXP(N11)*N26 -> 59922.127 | ... ALR27: =EXP(ALR11)*ALR26 -> 55213.613
F28: =F27+1 -> 9 | G28: =EXP(G12)*G27 -> 54822.136 | H28: =EXP(H12)*H27 -> 48800.495 | I28: =EXP(I12)*I27 -> 56178.467 | J28: =EXP(J12)*J27 -> 57531.998 | K28: =EXP(K12)*K27 -> 72658.399 | L28: =EXP(L12)*L27 -> 69945.613 | M28: =EXP(M12)*M27 -> 54361.188 | N28: =EXP(N12)*N27 -> 59366.246 | ... ALR28: =EXP(ALR12)*ALR27 -> 58065.339
F29: =F28+1 -> 10 | G29: =EXP(G13)*G28 -> 55130.923 | H29: =EXP(H13)*H28 -> 51527.139 | I29: =EXP(I13)*I28 -> 54836.474 | J29: =EXP(J13)*J28 -> 56616.347 | K29: =EXP(K13)*K28 -> 76487.174 | L29: =EXP(L13)*L28 -> 69375.438 | M29: =EXP(M13)*M28 -> 54508.61 | N29: =EXP(N13)*N28 -> 58610.406 | ... ALR29: =EXP(ALR13)*ALR28 -> 59524.349
F30: =F29+1 -> 11 | G30: =EXP(G14)*G29 -> 52551.987 | H30: =EXP(H14)*H29 -> 50366.034 | I30: =EXP(I14)*I29 -> 60555.554 | J30: =EXP(J14)*J29 -> 59109.138 | K30: =EXP(K14)*K29 -> 81653.087 | L30: =EXP(L14)*L29 -> 77776.55 | M30: =EXP(M14)*M29 -> 51192.03 | N30: =EXP(N14)*N29 -> 52689.348 | ... ALR30: =EXP(ALR14)*ALR29 -> 56188.879
F31: =F30+1 -> 12 | G31: =EXP(G15)*G30 -> 57757.875 | H31: =EXP(H15)*H30 -> 52181.634 | I31: =EXP(I15)*I30 -> 58183.41 | J31: =EXP(J15)*J30 -> 54936.742 | K31: =EXP(K15)*K30 -> 81455.018 | L31: =EXP(L15)*L30 -> 77180.136 | M31: =EXP(M15)*M30 -> 52188.996 | N31: =EXP(N15)*N30 -> 55649.157 | ... ALR31: =EXP(ALR15)*ALR30 -> 60914.387

Sheet Utility Functions
A1: Chosen utility functions | G1: Sim No. | H1: =1 -> 1 | I1: 2 | J1: 3 | K1: 4 | L1: 5 | M1: 6 | N1: 7 | O1: 8 | P1: 9 | Q1: 10 | R1: 11 | S1: 12 | T1: 13 | U1: 14 | V1: 15 | W1: 16 | X1: 17 | Y1: 18 | Z1: 19 | AA1: 20 | AB1: 21 | AC1: 22 | AD1: 23 | AE1: 24 | AF1: 25 | AG1: 26 | AH1: 27 | AI1: 28 | AJ1: 29 | AK1: 30 | AL1: 31 | AM1: 32 | AN1: 33 | AO1: 34 | AP1: 35 | AQ1: 36 | AR1: 37 | AS1: 38 | AT1: 39 | AU1: 40 | AV1: 41 | AW1: 42 | AX1: 43 | AY1: 44 | AZ1: 45 | BA1: 46 | BB1: 47 | BC1: 48 | BD1: 49 | BE1: 50 | BF1: 51 | BG1: 52 | BH1: 53 | BI1: 54 | BJ1: 55 | BK1: 56 | BL1: 57 | BM1: 58 | BN1: 59 | BO1: 60 | BP1: 61 | BQ1: 62 | BR1: 63 | BS1: 64 | BT1: 65 | BU1: 66 | BV1: 67 | BW1: 68 | BX1: 69 | BY1: 70 | BZ1: 71 | CA1: 72 | CB1: 73 | CC1: 74 | CD1: 75 | CE1: 76 | CF1: 77 | CG1: 78 | CH1: 79 | CI1: 80 | CJ1: 81 | CK1: 82 | CL1: 83 | CM1: 84 | CN1: 85 | CO1: 86 | CP1: 87 | CQ1: 88 | CR1: 89 | CS1: 90 | CT1: 91 | CU1: 92 | CV1: 93 | CW1: 94 | CX1: 95 | CY1: 96 | CZ1: 97 | DA1: 98 | DB1: 99 | DC1: 100 | DD1: 101 | DE1: 102 | DF1: 103 | DG1: 104 | DH1: 105 | DI1: 106 | DJ1: 107 | DK1: 108 | DL1: 109 | DM1: 110 | DN1: 111 | DO1: 112 | DP1: 113 | DQ1: 114 | DR1: 115 | DS1: 116 | DT1: 117 | DU1: 118 | DV1: 119 | DW1: 120 | DX1: 121 | DY1: 122 | DZ1: 123 | EA1: 124 | EB1: 125 | EC1: 126 | ED1: 127 | EE1: 128 | EF1: 129 | EG1: 130 | EH1: 131 | EI1: 132 | EJ1: 133 | EK1: 134 | EL1: 135 | EM1: 136 | EN1: 137 | EO1: 138 | EP1: 139 | EQ1: 140 | ER1: 141 | ES1: 142 | ET1: 143 | EU1: 144 | EV1: 145 | EW1: 146 | EX1: 147 | EY1: 148 | EZ1: 149 | FA1: 150 | FB1: 151 | FC1: 152 | FD1: 153 | FE1: 154 | FF1: 155 | FG1: 156 | FH1: 157 | FI1: 158 | FJ1: 159 | FK1: 160 | FL1: 161 | FM1: 162 | FN1: 163 | FO1: 164 | FP1: 165 | FQ1: 166 | FR1: 167 | FS1: 168 | FT1: 169 | FU1: 170 | FV1: 171 | FW1: 172 | FX1: 173 | FY1: 174 | FZ1: 175 | GA1: 176 | GB1: 177 | GC1: 178 | GD1: 179 | GE1: 180 | GF1: 181 | GG1: 182 | GH1: 183 | GI1: 184 | GJ1: 185 | GK1: 186 | GL1: 187 | GM1: 188 | GN1: 189 | GO1: 190 | GP1: 191 | GQ1: 192 | GR1: 193 | GS1: 194 | GT1: 195 | GU1: 196 | GV1: 197 | GW1: 198 | GX1: 199 | GY1: 200 | GZ1: 201 | HA1: 202 | HB1: 203 | HC1: 204 | HD1: 205 | HE1: 206 | HF1: 207 | HG1: 208 | HH1: 209 | HI1: 210 | HJ1: 211 | HK1: 212 | HL1: 213 | HM1: 214 | HN1: 215 | HO1: 216 | HP1: 217 | HQ1: 218 | HR1: 219 | HS1: 220 | HT1: 221 | HU1: 222 | HV1: 223 | HW1: 224 | HX1: 225 | HY1: 226 | HZ1: 227 | IA1: 228 | IB1: 229 | IC1: 230 | ID1: 231 | IE1: 232 | IF1: 233 | IG1: 234 | IH1: 235 | II1: 236 | IJ1: 237 | IK1: 238 | IL1: 239 | IM1: 240 | IN1: 241 | IO1: 242 | IP1: 243 | IQ1: 244 | IR1: 245 | IS1: 246 | IT1: 247 | IU1: 248 | IV1: 249 | IW1: 250 | IX1: 251 | IY1: 252 | IZ1: 253 | JA1: 254 | JB1: 255 | JC1: 256 | JD1: 257 | JE1: 258 | JF1: 259 | JG1: 260 | JH1: 261 | JI1: 262 | JJ1: 263 | JK1: 264 | JL1: 265 | JM1: 266 | JN1: 267 | JO1: 268 | JP1: 269 | JQ1: 270 | JR1: 271 | JS1: 272 | JT1: 273 | JU1: 274 | JV1: 275 | JW1: 276 | JX1: 277 | JY1: 278 | JZ1: 279 | KA1: 280 | KB1: 281 | KC1: 282 | KD1: 283 | KE1: 284 | KF1: 285 | KG1: 286 | KH1: 287 | KI1: 288 | KJ1: 289 | KK1: 290 | KL1: 291 | KM1: 292 | KN1: 293 | KO1: 294 | KP1: 295 | KQ1: 296 | KR1: 297 | KS1: 298 | KT1: 299 | KU1: 300 | KV1: 301 | KW1: 302 | KX1: 303 | KY1: 304 | KZ1: 305 | LA1: 306 | LB1: 307 | LC1: 308 | LD1: 309 | LE1: 310 | LF1: 311 | LG1: 312 | LH1: 313 | LI1: 314 | LJ1: 315 | LK1: 316 | LL1: 317 | LM1: 318 | LN1: 319 | LO1: 320 | LP1: 321 | LQ1: 322 | LR1: 323 | LS1: 324 | LT1: 325 | LU1: 326 | LV1: 327 | LW1: 328 | LX1: 329 | LY1: 330 | LZ1: 331 | MA1: 332 | MB1: 333 | MC1: 334 | MD1: 335 | ME1: 336 | MF1: 337 | MG1: 338 | MH1: 339 | MI1: 340 | MJ1: 341 | MK1: 342 | ML1: 343 | MM1: 344 | MN1: 345 | MO1: 346 | MP1: 347 | MQ1: 348 | MR1: 349 | MS1: 350 | MT1: 351 | MU1: 352 | MV1: 353 | MW1: 354 | MX1: 355 | MY1: 356 | MZ1: 357 | NA1: 358 | NB1: 359 | NC1: 360 | ND1: 361 | NE1: 362 | NF1: 363 | NG1: 364 | NH1: 365 | NI1: 366 | NJ1: 367 | NK1: 368 | NL1: 369 | NM1: 370 | NN1: 371 | NO1: 372 | NP1: 373 | NQ1: 374 | NR1: 375 | NS1: 376 | NT1: 377 | NU1: 378 | NV1: 379 | NW1: 380 | NX1: 381 | NY1: 382 | NZ1: 383 | OA1: 384 | OB1: 385 | OC1: 386 | OD1: 387 | OE1: 388 | OF1: 389 | OG1: 390 | OH1: 391 | OI1: 392 | OJ1: 393 | OK1: 394 | OL1: 395 | OM1: 396 | ON1: 397 | OO1: 398 | OP1: 399 | OQ1: 400 | OR1: 401 | OS1: 402 | OT1: 403 | OU1: 404 | OV1: 405 | OW1: 406 | OX1: 407 | OY1: 408 | OZ1: 409 | PA1: 410 | PB1: 411 | PC1: 412 | PD1: 413 | PE1: 414 | PF1: 415 | PG1: 416 | PH1: 417 | PI1: 418 | PJ1: 419 | PK1: 420 | PL1: 421 | PM1: 422 | PN1: 423 | PO1: 424 | PP1: 425 | PQ1: 426 | PR1: 427 | PS1: 428 | PT1: 429 | PU1: 430 | PV1: 431 | PW1: 432 | PX1: 433 | PY1: 434 | PZ1: 435 | QA1: 436 | QB1: 437 | QC1: 438 | QD1: 439 | QE1: 440 | QF1: 441 | QG1: 442 | QH1: 443 | QI1: 444 | QJ1: 445 | QK1: 446 | QL1: 447 | QM1: 448 | QN1: 449 | QO1: 450 | QP1: 451 | QQ1: 452 | QR1: 453 | QS1: 454 | QT1: 455 | QU1: 456 | QV1: 457 | QW1: 458 | QX1: 459 | QY1: 460 | QZ1: 461 | RA1: 462 | RB1: 463 | RC1: 464 | RD1: 465 | RE1: 466 | RF1: 467 | RG1: 468 | RH1: 469 | RI1: 470 | RJ1: 471 | RK1: 472 | RL1: 473 | RM1: 474 | RN1: 475 | RO1: 476 | RP1: 477 | RQ1: 478 | RR1: 479 | RS1: 480 | RT1: 481 | RU1: 482 | RV1: 483 | RW1: 484 | RX1: 485 | RY1: 486 | RZ1: 487 | SA1: 488 | SB1: 489 | SC1: 490 | SD1: 491 | SE1: 492 | SF1: 493 | SG1: 494 | SH1: 495 | SI1: 496 | SJ1: 497 | SK1: 498 | SL1: 499 | SM1: 500 | SN1: 501 | SO1: 502 | SP1: 503 | SQ1: 504 | SR1: 505 | SS1: 506 | ST1: 507 | SU1: 508 | SV1: 509 | SW1: 510 | SX1: 511 | SY1: 512 | SZ1: 513 | TA1: 514 | TB1: 515 | TC1: 516 | TD1: 517 | TE1: 518 | TF1: 519 | TG1: 520 | TH1: 521 | TI1: 522 | TJ1: 523 | TK1: 524 | TL1: 525 | TM1: 526 | TN1: 527 | TO1: 528 | TP1: 529 | TQ1: 530 | TR1: 531 | TS1: 532 | TT1: 533 | TU1: 534 | TV1: 535 | TW1: 536 | TX1: 537 | TY1: 538 | TZ1: 539 | UA1: 540 | UB1: 541 | UC1: 542 | UD1: 543 | UE1: 544 | UF1: 545 | UG1: 546 | UH1: 547 | UI1: 548 | UJ1: 549 | UK1: 550 | UL1: 551 | UM1: 552 | UN1: 553 | UO1: 554 | UP1: 555 | UQ1: 556 | UR1: 557 | US1: 558 | UT1: 559 | UU1: 560 | UV1: 561 | UW1: 562 | UX1: 563 | UY1: 564 | UZ1: 565 | VA1: 566 | VB1: 567 | VC1: 568 | VD1: 569 | VE1: 570 | VF1: 571 | VG1: 572 | VH1: 573 | VI1: 574 | VJ1: 575 | VK1: 576 | VL1: 577 | VM1: 578 | VN1: 579 | VO1: 580 | VP1: 581 | VQ1: 582 | VR1: 583 | VS1: 584 | VT1: 585 | VU1: 586 | VV1: 587 | VW1: 588 | VX1: 589 | VY1: 590 | VZ1: 591 | WA1: 592 | WB1: 593 | WC1: 594 | WD1: 595 | WE1: 596 | WF1: 597 | WG1: 598 | WH1: 599 | WI1: 600 | WJ1: 601 | WK1: 602 | WL1: 603 | WM1: 604 | WN1: 605 | WO1: 606 | WP1: 607 | WQ1: 608 | WR1: 609 | WS1: 610 | WT1: 611 | WU1: 612 | WV1: 613 | WW1: 614 | WX1: 615 | WY1: 616 | WZ1: 617 | XA1: 618 | XB1: 619 | XC1: 620 | XD1: 621 | XE1: 622 | XF1: 623 | XG1: 624 | XH1: 625 | XI1: 626 | XJ1: 627 | XK1: 628 | XL1: 629 | XM1: 630 | XN1: 631 | XO1: 632 | XP1: 633 | XQ1: 634 | XR1: 635 | XS1: 636 | XT1: 637 | XU1: 638 | XV1: 639 | XW1: 640 | XX1: 641 | XY1: 642 | XZ1: 643 | YA1: 644 | YB1: 645 | YC1: 646 | YD1: 647 | YE1: 648 | YF1: 649 | YG1: 650 | YH1: 651 | YI1: 652 | YJ1: 653 | YK1: 654 | YL1: 655 | YM1: 656 | YN1: 657 | YO1: 658 | YP1: 659 | YQ1: 660 | YR1: 661 | YS1: 662 | YT1: 663 | YU1: 664 | YV1: 665 | YW1: 666 | YX1: 667 | YY1: 668 | YZ1: 669 | ZA1: 670 | ZB1: 671 | ZC1: 672 | ZD1: 673 | ZE1: 674 | ZF1: 675 | ZG1: 676 | ZH1: 677 | ZI1: 678 | ZJ1: 679 | ZK1: 680 | ZL1: 681 | ZM1: 682 | ZN1: 683 | ZO1: 684 | ZP1: 685 | ZQ1: 686 | ZR1: 687 | ZS1: 688 | ZT1: 689 | ZU1: 690 | ZV1: 691 | ZW1: 692 | ZX1: 693 | ZY1: 694 | ZZ1: 695 | AAA1: 696 | AAB1: 697 | AAC1: 698 | AAD1: 699 | AAE1: 700 | AAF1: 701 | AAG1: 702 | AAH1: 703 | AAI1: 704 | AAJ1: 705 | AAK1: 706 | AAL1: 707 | AAM1: 708 | AAN1: 709 | AAO1: 710 | AAP1: 711 | AAQ1: 712 | AAR1: 713 | AAS1: 714 | AAT1: 715 | AAU1: 716 | AAV1: 717 | AAW1: 718 | AAX1: 719 | AAY1: 720 | AAZ1: 721 | ABA1: 722 | ABB1: 723 | ABC1: 724 | ABD1: 725 | ABE1: 726 | ABF1: 727 | ABG1: 728 | ABH1: 729 | ABI1: 730 | ABJ1: 731 | ABK1: 732 | ABL1: 733 | ABM1: 734 | ABN1: 735 | ABO1: 736 | ABP1: 737 | ABQ1: 738 | ABR1: 739 | ABS1: 740 | ABT1: 741 | ABU1: 742 | ABV1: 743 | ABW1: 744 | ABX1: 745 | ABY1: 746 | ABZ1: 747 | ACA1: 748 | ACB1: 749 | ACC1: 750 | ACD1: 751 | ACE1: 752 | ACF1: 753 | ACG1: 754 | ACH1: 755 | ACI1: 756 | ACJ1: 757 | ACK1: 758 | ACL1: 759 | ACM1: 760 | ACN1: 761 | ACO1: 762 | ACP1: 763 | ACQ1: 764 | ACR1: 765 | ACS1: 766 | ACT1: 767 | ACU1: 768 | ACV1: 769 | ACW1: 770 | ACX1: 771 | ACY1: 772 | ACZ1: 773 | ADA1: 774 | ADB1: 775 | ADC1: 776 | ADD1: 777 | ADE1: 778 | ADF1: 779 | ADG1: 780 | ADH1: 781 | ADI1: 782 | ADJ1: 783 | ADK1: 784 | ADL1: 785 | ADM1: 786 | ADN1: 787 | ADO1: 788 | ADP1: 789 | ADQ1: 790 | ADR1: 791 | ADS1: 792 | ADT1: 793 | ADU1: 794 | ADV1: 795 | ADW1: 796 | ADX1: 797 | ADY1: 798 | ADZ1: 799 | AEA1: 800 | AEB1: 801 | AEC1: 802 | AED1: 803 | AEE1: 804 | AEF1: 805 | AEG1: 806 | AEH1: 807 | AEI1: 808 | AEJ1: 809 | AEK1: 810 | AEL1: 811 | AEM1: 812 | AEN1: 813 | AEO1: 814 | AEP1: 815 | AEQ1: 816 | AER1: 817 | AES1: 818 | AET1: 819 | AEU1: 820 | AEV1: 821 | AEW1: 822 | AEX1: 823 | AEY1: 824 | AEZ1: 825 | AFA1: 826 | AFB1: 827 | AFC1: 828 | AFD1: 829 | AFE1: 830 | AFF1: 831 | AFG1: 832 | AFH1: 833 | AFI1: 834 | AFJ1: 835 | AFK1: 836 | AFL1: 837 | AFM1: 838 | AFN1: 839 | AFO1: 840 | AFP1: 841 | AFQ1: 842 | AFR1: 843 | AFS1: 844 | AFT1: 845 | AFU1: 846 | AFV1: 847 | AFW1: 848 | AFX1: 849 | AFY1: 850 | AFZ1: 851 | AGA1: 852 | AGB1: 853 | AGC1: 854 | AGD1: 855 | AGE1: 856 | AGF1: 857 | AGG1: 858 | AGH1: 859 | AGI1: 860 | AGJ1: 861 | AGK1: 862 | AGL1: 863 | AGM1: 864 | AGN1: 865 | AGO1: 866 | AGP1: 867 | AGQ1: 868 | AGR1: 869 | AGS1: 870 | AGT1: 871 | AGU1: 872 | AGV1: 873 | AGW1: 874 | AGX1: 875 | AGY1: 876 | AGZ1: 877 | AHA1: 878 | AHB1: 879 | AHC1: 880 | AHD1: 881 | AHE1: 882 | AHF1: 883 | AHG1: 884 | AHH1: 885 | AHI1: 886 | AHJ1: 887 | AHK1: 888 | AHL1: 889 | AHM1: 890 | AHN1: 891 | AHO1: 892 | AHP1: 893 | AHQ1: 894 | AHR1: 895 | AHS1: 896 | AHT1: 897 | AHU1: 898 | AHV1: 899 | AHW1: 900 | AHX1: 901 | AHY1: 902 | AHZ1: 903 | AIA1: 904 | AIB1: 905 | AIC1: 906 | AID1: 907 | AIE1: 908 | AIF1: 909 | AIG1: 910 | AIH1: 911 | AII1: 912 | AIJ1: 913 | AIK1: 914 | AIL1: 915 | AIM1: 916 | AIN1: 917 | AIO1: 918 | AIP1: 919 | AIQ1: 920 | AIR1: 921 | AIS1: 922 | AIT1: 923 | AIU1: 924 | AIV1: 925 | AIW1: 926 | AIX1: 927 | AIY1: 928 | AIZ1: 929 | AJA1: 930 | AJB1: 931 | AJC1: 932 | AJD1: 933 | AJE1: 934 | AJF1: 935 | AJG1: 936 | AJH1: 937 | AJI1: 938 | AJJ1: 939 | AJK1: 940 | AJL1: 941 | AJM1: 942 | AJN1: 943 | AJO1: 944 | AJP1: 945 | AJQ1: 946 | AJR1: 947 | AJS1: 948 | AJT1: 949 | AJU1: 950 | AJV1: 951 | AJW1: 952 | AJX1: 953 | AJY1: 954 | AJZ1: 955 | AKA1: 956 | AKB1: 957 | AKC1: 958 | AKD1: 959 | AKE1: 960 | AKF1: 961 | AKG1: 962 | AKH1: 963 | AKI1: 964 | AKJ1: 965 | AKK1: 966 | AKL1: 967 | AKM1: 968 | AKN1: 969 | AKO1: 970 | AKP1: 971 | AKQ1: 972 | AKR1: 973 | AKS1: 974 | AKT1: 975 | AKU1: 976 | AKV1: 977 | AKW1: 978 | AKX1: 979 | AKY1: 980 | AKZ1: 981 | ALA1: 982 | ALB1: 983 | ALC1: 984 | ALD1: 985 | ALE1: 986 | ALF1: 987 | ALG1: 988 | ALH1: 989 | ALI1: 990 | ALJ1: 991 | ALK1: 992 | ALL1: 993 | ALM1: 994 | ALN1: 995 | ALO1: 996 | ALP1: 997 | ALQ1: 998 | ALR1: 999 | ALS1: 1000
A2: Log | B2: u(x) = log(x) | E2: x>0 | G2: Acc. Wealth | H2: ='Simulations | Acc. Wealth'!G31 -> 57757.875 | I2: ='Simulations | Acc. Wealth'!H31 -> 52181.634 | J2: ='Simulations | Acc. Wealth'!I31 -> 58183.41 | K2: ='Simulations | Acc. Wealth'!J31 -> 54936.742 | L2: ='Simulations | Acc. Wealth'!K31 -> 81455.018 | M2: ='Simulations | Acc. Wealth'!L31 -> 77180.136 | N2: ='Simulations | Acc. Wealth'!M31 -> 52188.996 | O2: ='Simulations | Acc. Wealth'!N31 -> 55649.157 | ... ALS2: ='Simulations | Acc. Wealth'!ALR31 -> 60914.387
A3: Quadratic | B3: u(x) = x - bx^2 | E3: neg inf < x < 1/2b | G3: Log | H3: =LOG(H2) -> 4.7616112 | I3: =LOG(I2) -> 4.7175177 | J3: =LOG(J2) -> 4.7647992 | K3: =LOG(K2) -> 4.7398629 | L3: =LOG(L2) -> 4.9109178 | M3: =LOG(M2) -> 4.8875055 | N3: =LOG(N2) -> 4.7175789 | O3: =LOG(O2) -> 4.7454586 | ... ALS3: =LOG(ALS2) -> 4.7847199
A4: Exponential | B4: u(x) = 1 - exp(-ax) | E4: - | G4: Quadratic | H4: =H2-$C$8*H2^2 -> 43294.147 | I4: =I2-$C$8*I2^2 -> 40375.895 | J4: =J2-$C$8*J2^2 -> 43505.772 | K4: =K2-$C$8*K2^2 -> 41851.443 | L4: =L2-$C$8*L2^2 -> 52688.087 | M4: =M2-$C$8*M2^2 -> 51353.436 | N4: =N2-$C$8*N2^2 -> 40379.925 | O4: =O2-$C$8*O2^2 -> 42222.28 | ... ALS4: =ALS2-$C$8*ALS2^2 -> 44826.552
A5: Power | B5: u(x) = (x^γ - 1) / γ | E5: γ<1, x>0 | G5: Exponential | H5: =1-EXP(-H2*$C$9) -> 0.6327381 | I5: =1-EXP(-I2*$C$9) -> 0.59544709 | J5: =1-EXP(-J2*$C$9) -> 0.6354385 | K5: =1-EXP(-K2*$C$9) -> 0.61432255 | L5: =1-EXP(-L2*$C$9) -> 0.75650371 | M5: =1-EXP(-M2*$C$9) -> 0.73776531 | N5: =1-EXP(-N2*$C$9) -> 0.59549874 | O5: =1-EXP(-O2*$C$9) -> 0.61905837 | ... ALS5: =1-EXP(-ALS2*$C$9) -> 0.65230258
G6: Power | H6: =((H2^$C$10) -1)/$C$10 -> 10.964021 | I6: =((I2^$C$10) -1)/$C$10 -> 10.862492 | J6: =((J2^$C$10) -1)/$C$10 -> 10.971362 | K6: =((K2^$C$10) -1)/$C$10 -> 10.913944 | L6: =((L2^$C$10) -1)/$C$10 -> 11.307813 | M6: =((M2^$C$10) -1)/$C$10 -> 11.253904 | N6: =((N2^$C$10) -1)/$C$10 -> 10.862633 | O6: =((O2^$C$10) -1)/$C$10 -> 10.926828 | ... ALS6: =((ALS2^$C$10) -1)/$C$10 -> 11.017231
A7: Parameters | ALO7: \
A8: Quadratic | B8: b | C8: =1/(4*57661) -> 4.3356862e-06
A9: Exp | B9: a | C9: =1/57661 -> 1.7342745e-05
A10: Power | B10: γ | C10: 1e-07
A12: Acc Wealth (Rf) | C12: ='Simulations | Acc. Wealth'!D16 -> 58223.945
A13: Log | C13: =LOG(C12) -> 4.7651016
A14: Quadratic | C14: =C12-C8*C12^2 -> 43525.848
A15: Exponential | C15: =1-EXP(-C12*C9) -> 0.63569469
A16: Power | C16: =C22 -> 10.972058
A18: Average Utilities (Apple) | C18: Rf Utilities
A19: Log | B19: =AVERAGE(H3:ALS3) -> 4.7710348 | C19: =C13 -> 4.7651016
A20: Quadratic | B20: =AVERAGE(H4:ALS4) -> 43894.867 | C20: =C14 -> 43525.848
A21: Exponential | B21: =AVERAGE(H5:ALS5) -> 0.64060699 | C21: =C15 -> 0.63569469
A22: Power | B22: =AVERAGE(H6:ALS6) -> 10.98572 | C22: =((C12^C10)-1)/C10 -> 10.972058
